Workbook

Sheet Full Report  JULY 25 Report
A1: AMNESTY INTERNATIONAL KENYA 2025 REPORT | C1: TOTAL BUDGET | D1: ACTUAL COSTS JULY 25 | E1: VARIANCE | F1: % SPENT | G1: Q1 BUDGET | H1: Q2 BUDGET | I1: Q3 BUDGET | J1: Q4 BUDGET
B3: REVENUE ANALYSIS 2025
B4: Balance b/f from 2024-estimates DEFICIT | C4: =-61380310/2 -> -30690155
B5: 2025 RAM Allocation | C5: 126000000
B6: FIF Allocation | C6: 9500000
B7: HEWLETT FOUNDATION | C7: 51658737
B8: BOTNAR | C8: ='[1]Aproved Budget 2025 .'!F9 -> 14929325
B9: RELIEF FUNDS
B10: HEINRICH BOLL FOUNDATION | C10: 7010000
B11: MEMBERSHIP
B12: INTEREST
B13: TOTAL REVENUE 2025 | C13: =SUM(C4:C12) -> 178407907 | D13: =D125 -> 107444960 | E13: =C13-D13 -> 70962947 | F13: =D13/C13 -> 0.60224326
B15: VARIANCE
B17: EXPENDITURE ALLOCATION 2025
A18: Budget Codes | B18: Result Areas
A19: 2100/000 | B19: Movement Building
A20: 2100/001 | B20: Events and workshops | C20: =#REF!+#REF!+#REF!+#REF! -> #REF! | D20: ='[1]Trail Bal. JULY 2025'!J52 -> 1908300 | E20: =C20-D20 -> #REF! | F20: =D20/C20 -> #REF! | G20: 900000 | H20: 800000 | I20: 700000 | J20: 600000
A21: 2100/002 | B21: Research, publications and tools | C21: =#REF!+#REF!+#REF!+#REF! -> #REF! | D21: 0 | E21: =C21-D21 -> #REF! | F21: =D21/C21 -> #REF! | G21: 750000 | H21: 0 | I21: 750000 | J21: 0
A22: 2100/003 | B22: National mission travel | C22: =#REF!+#REF!+#REF!+#REF! -> #REF! | D22: ='[1]Trail Bal. JULY 2025'!D54 -> 95700 | E22: =C22-D22 -> #REF! | F22: =D22/C22 -> #REF! | G22: 250000 | H22: 200000 | I22: 300000 | J22: 250000
A23: 2100/004 | B23: Project rapid response and mini grants | C23: =#REF!+#REF!+#REF!+#REF! -> #REF! | D23: 0 | E23: =C23-D23 -> #REF! | G23: 300000 | H23: 1000000 | I23: 1500000 | J23: 2000000
A24: 2100/005 | B24: Campaign Manager (Emily) | C24: =#REF!+#REF!+#REF!+#REF! -> #REF! | D24: ='[1]Trail Bal. JULY 2025'!D56 -> 3724378.1 | E24: =C24-D24 -> #REF! | F24: =D24/C24 -> #REF! | G24: =C24/4 -> #REF! | H24: =G24 -> #REF! | I24: =H24 -> #REF! | J24: =I24 -> #REF!
A25: 2100/006 | B25: Campaign Officer (James) | C25: =#REF!+#REF!+#REF!+#REF! -> #REF! | D25: ='[1]Trail Bal. JULY 2025'!D57-D32 -> 1903867.5 | E25: =C25-D25 -> #REF! | F25: =D25/C25 -> #REF! | G25: =C25/4 -> #REF! | H25: =G25 -> #REF! | I25: =H25 -> #REF! | J25: =I25 -> #REF!
A26: 2100/007 | B26: Campaign Officer (Amy) | C26: =#REF!+#REF!+#REF!+#REF! -> #REF! | D26: ='[1]Trail Bal. JULY 2025'!D58 -> 1825892 | E26: =C26-D26 -> #REF! | F26: =D26/C26 -> #REF! | G26: =C26/4 -> #REF! | H26: =G26 -> #REF! | I26: =H26 -> #REF! | J26: =I26 -> #REF!
A27: 2100/008 | B27: Impact Reporting Officer (vacant) 50% | C27: =#REF!+#REF!+#REF!+#REF! -> #REF! | D27: 0 | E27: =C27-D27 -> #REF! | G27: =C27/4 -> #REF! | H27: =G27 -> #REF! | I27: =H27 -> #REF! | J27: =I27 -> #REF!
A28: 2100/009 | B28: Monitoring, Evaluation & Learning | C28: =#REF!+#REF!+#REF!+#REF! -> #REF! | D28: ='[1]Trail Bal. JULY 2025'!J60 -> 442770 | E28: =C28-D28 -> #REF! | F28: =D28/C28 -> #REF! | G28: 250000 | H28: 100000 | I28: 300000 | J28: =C28-G28-H28-I28 -> #REF!
A29: 2100/010 | B29: Campaign Officer (Eunice) | C29: =#REF!+#REF!+#REF!+#REF! -> #REF! | D29: ='[1]Trail Bal. JULY 2025'!D61 -> 1197897.4 | E29: =C29-D29 -> #REF! | F29: =D29/C29 -> #REF! | G29: =C29/4 -> #REF! | H29: =G29 -> #REF! | I29: =H29 -> #REF! | J29: =I29 -> #REF!
A30: 2100/011 | B30: Membership | C30: =#REF!+#REF!+#REF!+#REF!-600000 -> #REF! | D30: ='[1]Trail Bal. JULY 2025'!D62-D31 -> 510234 | E30: =C30-D30 -> #REF! | F30: =D30/C30 -> #REF! | G30: 900000 | H30: 1000000 | I30: 1000000 | J30: 600000
A31: 2100/012 | B31: Merchandise | C31: =#REF!+#REF!+#REF!+#REF! -> #REF! | D31: 263716 | E31: =C31-D31 -> #REF! | F31: =D31/C31 -> #REF!
B32: Staff Gratuaity -James Kimila | D32: 613123 | F32: =D32/C32 -> #DIV/0!
B33: Total Movement Building | C33: =SUM(C20:C31) -> #REF! | D33: =SUM(D20:D32) -> 12485878 | E33: =SUM(E20:E31) -> #REF! | F33: =D33/C33 -> #REF! | G33: =SUM(G20:G30) -> #REF! | H33: =SUM(H20:H30) -> #REF! | I33: =SUM(I20:I30) -> #REF! | J33: =SUM(J20:J30) -> #REF! | K33: =D33-'[1]Trail Bal. JULY 2025'!J51 -> 0
A35: 2400/000 | B35: Equality and Anti-Discrimination
A36: 2400/001 | B36: Events and workshops | C36: =#REF!+#REF!+#REF!+#REF! -> #REF! | D36: ='[1]Trail Bal. JULY 2025'!D77 -> 538900 | E36: =C36-D36 -> #REF! | F36: =D36/C36 -> #REF! | G36: 1000000 | H36: 800000 | I36: 1000000 | J36: 500000
A37: 2400/002 | B37: Research, publications and tools | C37: =#REF!+#REF!+#REF!+#REF! -> #REF! | D37: ='[1]Trail Bal. JULY 2025'!D78 -> 616688 | E37: =C37-D37 -> #REF! | F37: =D37/C37 -> #REF! | G37: 200000 | H37: 250000 | I37: 500000 | J37: 550000
A38: 2400/003 | B38: National mission travel | C38: =#REF!+#REF!+#REF!+#REF! -> #REF! | D38: ='[1]Trail Bal. JULY 2025'!D79 -> 211710.02 | E38: =C38-D38 -> #REF! | F38: =D38/C38 -> #REF! | G38: 250000 | H38: 300000 | I38: 400000 | J38: 350000
A39: 2400/004 | B39: Project rapid response and mini grants | C39: =#REF!+#REF!+#REF!+#REF! -> #REF! | D39: ='[1]Trail Bal. JULY 2025'!D80 -> 126672 | E39: =C39-D39 -> #REF! | F39: =D39/C39 -> #REF! | G39: 400000 | H39: 600000 | I39: 1000000 | J39: 1000000
A40: 2400/005 | B40: Campaign Manager (Zaina) | C40: =#REF!+#REF!+#REF!+#REF! -> #REF! | D40: ='[1]Trail Bal. JULY 2025'!D81 -> 3164375.1 | E40: =C40-D40 -> #REF! | F40: =D40/C40 -> #REF! | G40: =C40/4 -> #REF! | H40: =G40 -> #REF! | I40: =H40 -> #REF! | J40: =I40 -> #REF!
A41: 2400/006 | B41: Campaign Officer (Gaudence) | C41: =#REF!+#REF!+#REF!+#REF! -> #REF! | D41: ='[1]Trail Bal. JULY 2025'!D82 -> 1279635.9 | E41: =C41-D41 -> #REF! | F41: =D41/C41 -> #REF! | G41: =C41/4 -> #REF! | H41: =G41 -> #REF! | I41: =H41 -> #REF! | J41: =I41 -> #REF!
B42: Total Equality and Anti-Discrimination | C42: =SUM(C36:C41) -> #REF! | D42: =SUM(D36:D41) -> 5937981.1 | E42: =SUM(E36:E41) -> #REF! | F42: =D42/C42 -> #REF! | G42: =SUM(G36:G41) -> #REF! | H42: =SUM(H36:H41) -> #REF! | I42: =SUM(I36:I41) -> #REF! | J42: =SUM(J36:J41) -> #REF!
A44: 2500/000 | B44: Civil Liberties
A45: 2500/001 | B45: Events and workshops | C45: =#REF!+#REF!+#REF!+#REF! -> #REF! | D45: ='[1]Trail Bal. JULY 2025'!J86 -> 192000 | E45: =C45-D45 -> #REF! | G45: 700000 | H45: 1700000 | I45: 1000000 | J45: 1600000
...

Sheet Trial Bal&Budget 2025
A1: Trial Balance/Budget
L2: 9/4/2025 9:33 AM
L3: Page 1 / 1
L6: FKIBUE
A7: Period: 01/01/25..07/31/25
A11: AMNESTY INTERNATIONAL KENYA
A14: Budget Filter: 2025BUDGET
A15: G/L Account: Date Filter: 01/01/25..07/31/25, Budget Filter: 2025BUDGET
D17: Net Change | N17: Balance
A19: No. | B19: Name | D19: Debit | F19: Credit | H19: % of | K19: Budget | N19: Debit | P19: Credit | R19: % of | T19: Budget
A23: 1000/000 | B23: Income Statement
A24: 1000/020 | B24: Total Revenue | F24: 1.6034821e+08 | P24: 1.6034821e+08
A25: 1000/050 | B25: TOTAL FUNDING | F25: 1.6034821e+08 | P25: 1.6034821e+08
A26: 1000/100 | B26: RAM FUNDS | F26: 1.3622817e+08 | P26: 1.3622817e+08
A27: 1000/200 | B27: PORTICUS
A28: 1000/300 | B28: COMIC RELIEF
A29: 1000/400 | B29: MEMBERSHIP FEES | F29: 315120.25 | P29: 315120.25
A30: 1000/500 | B30: MERCHANDISE AND RETAIL | F30: 80352 | P30: 80352
A31: 1000/600 | B31: RELIEF FUNDS | F31: 1820452.1 | P31: 1820452.1
A32: 1000/700 | B32: FOREST PEOPLE PROGRAMME
A33: 1000/800 | B33: UNDP KENYA
A34: 1000/900 | B34: HEWLETT FOUNDATION
A35: 1100/000 | B35: FORD FOUNDATION
A36: 1100/100 | B36: MUSIC AFRICA FOUNDATION
A37: 1100/200 | B37: BOTNAR FOUNDATION | F37: 16338550 | P37: 16338550
A38: 1100/300 | B38: GIZ
A39: 1100/400 | B39: SWISS EMBASSY
A40: 1100/500 | B40: ROYAL EMBASSY OF NORWAY
A41: 1100/600 | B41: HEINRICH BOLL FOUNDATION | F41: 4907000 | P41: 4907000
A42: 1100/700 | B42: AMNESTY INTERNATIONAL UK SECTION
A43: 1100/800 | B43: German Grant
A44: 1200/000 | B44: UN-OHCHR
A45: 1500/000 | B45: INCOME - OTHER SPECIAL PROGRAMS
A46: 1600/000 | B46: INVESTMENT & BANK INTEREST | F46: 497934.92 | P46: 497934.92
A47: 1700/000 | B47: FOREIGN CURRENCY EXCHANGE GAIN
A48: 1700/100 | B48: UNREALISED EXCHANGE GAIN | F48: 65670.13 | P48: 65670.13
A49: 1800/000 | B49: DONATIONS | F49: 94960 | P49: 94960
A50: 2000/000 | B50: Total Expenditure | D50: 1.0747235e+08 | H50: 58.12992 | K50: 1.8488302e+08 | N50: 1.0747235e+08 | R50: 58.12992 | T50: 1.8488302e+08
A51: 2100/000 | B51: RESULT 1- HRE AND ACTIVISM | D51: 12485878 | H51: 81.001929 | K51: 15414297 | N51: 12485878 | R51: 81.001929 | T51: 15414297
A52: 2100/001 | B52: Events and Workshops | D52: 1908300 | H52: 133.44755 | K52: 1430000 | N52: 1908300 | R52: 133.44755 | T52: 1430000
...

Sheet Trail Bal. JULY 2025
A1: Trial Balance
H3: Wednesday, August 6, 2025
H4: Page 1 / 1
H7: FKIBUE
A8: Period: 01/01/25..07/31/25
A11: AMNESTY INTERNATIONAL KENYA
A15: G/L Account: Date Filter: 01/01/25..07/31/25
D17: Net Change | J17: Balance
A19: No. | B19: Name | D19: Debit | F19: Credit | J19: Debit | L19: Credit
A23: 1000/000 | B23: Income Statement
A24: 1000/020 | B24: Total Revenue | F24: 1.6031981e+08 | L24: 1.6031981e+08
A25: 1000/050 | B25: TOTAL FUNDING | F25: 1.6031981e+08 | L25: 1.6031981e+08
A26: 1000/100 | B26: RAM FUNDS | F26: 1.3622817e+08 | L26: 1.3622817e+08
A27: 1000/200 | B27: PORTICUS
A28: 1000/300 | B28: COMIC RELIEF
A29: 1000/400 | B29: MEMBERSHIP FEES | F29: 313987.5 | L29: 313987.5
A30: 1000/500 | B30: MERCHANDISE AND RETAIL | F30: 80352 | L30: 80352
A31: 1000/600 | B31: RELIEF FUNDS | F31: 1820452.1 | L31: 1820452.1
A32: 1000/700 | B32: FOREST PEOPLE PROGRAMME
A33: 1000/800 | B33: UNDP KENYA
A34: 1000/900 | B34: HEWLETT FOUNDATION
A35: 1100/000 | B35: FORD FOUNDATION
A36: 1100/100 | B36: MUSIC AFRICA FOUNDATION
A37: 1100/200 | B37: BOTNAR FOUNDATION | F37: 16338550 | L37: 16338550
A38: 1100/300 | B38: GIZ
A39: 1100/400 | B39: SWISS EMBASSY
A40: 1100/500 | B40: ROYAL EMBASSY OF NORWAY
A41: 1100/600 | B41: HEINRICH BOLL FOUNDATION | F41: 4907000 | L41: 4907000
A42: 1100/700 | B42: AMNESTY INTERNATIONAL UK SECTION
A43: 1100/800 | B43: German Grant
A44: 1200/000 | B44: UN-OHCHR
A45: 1500/000 | B45: INCOME - OTHER SPECIAL PROGRAMS
A46: 1600/000 | B46: INVESTMENT & BANK INTEREST | F46: 470671.75 | L46: 470671.75
A47: 1700/000 | B47: FOREIGN CURRENCY EXCHANGE GAIN
A48: 1700/100 | B48: UNREALISED EXCHANGE GAIN | F48: 65670.13 | L48: 65670.13
A49: 1800/000 | B49: DONATIONS | F49: 94960 | L49: 94960
A50: 2000/000 | B50: Total Expenditure | D50: 107444960 | J50: 107444960
A51: 2100/000 | B51: RESULT 1- HRE AND ACTIVISM | D51: 12485878 | J51: 12485878
A52: 2100/001 | B52: Events and Workshops | D52: 1908300 | J52: 1908300
A53: 2100/002 | B53: Research Publications and Tools
...
